<?xml version='1.0' encoding='utf-8'?>
<robot name="dummy">
    <material name="Blue">
        <color rgba="0.5 0.7 1.0 1.0"/>
    </material>
    <material name="red">
        <color rgba="1.0 0.0 0.0 1.0"/>
    </material>
    <link name="base_link" />
    <link name="link_0">
            <visual>
            <origin xyz="0.0 0.0 0" rpy="0.0 0.0 0" />
            <geometry>
                <mesh filename="package://dummy_description/meshes/link_0.STL"/>
            </geometry>
            <material name="Blue"/>
        </visual>
    </link> 

    <joint name="joint_0" type="fixed">
        <parent link="base_link" />
        <child link="link_0" />
        <origin xyz="0 0 0" rpy="0 0 0" />
    </joint>
    
    <link name="link_1">
            <visual>
            <origin xyz="0.0 0.0 0.0" rpy="0 0 0" />
            <geometry>
                <mesh filename="package://dummy_description/meshes/link_1.STL"/>
            </geometry>
            <material name="Blue"/>
        </visual>
    </link> 

    <joint name="joint_1" type="revolute">
        <parent link="link_0" />
        <child link="link_1" />
        <origin xyz="0 0 0.7" rpy="0 0 0" />
        <axis xyz="0 0 1"/>
        <limit lower="-3.14" upper="3.14" effort="0.5" velocity="0.5"/>
    </joint>
    
    <link name="link_2">
            <visual>
            <origin xyz="0 0 0" rpy="0 0 0" /> 
            <geometry>
                <mesh filename="package://dummy_description/meshes/link_2.STL"/>
            </geometry>
            <material name="Blue"/>
        </visual>
    </link>    

    <joint name="joint_2" type="revolute">
        <parent link="link_1" />
        <child link="link_2" />
        <origin xyz="-0.1 0.25 0" rpy="1.57 0 0" />
        <axis xyz="0 0 1"/>
        <limit lower="0" upper="3.14" effort="0.5" velocity="0.5"/>
    </joint>
    

    <link name="link_3">
            <visual>
            <origin xyz="0 0 0" rpy="0 0 0" />
            <geometry>
                <mesh filename="package://dummy_description/meshes/link_3.STL"/>
            </geometry>
            <material name="Blue"/>
        </visual>
    </link>    

    <joint name="joint_3" type="revolute">
        <parent link="link_2" />
        <child link="link_3" />
        <origin xyz="1 0 0.35" rpy="0 0 0" />
        <axis xyz="0 0 1"/>
        <limit lower="-1.57" upper="1.57" effort="0.5" velocity="0.5"/>
    </joint>
    <link name="link_4">
            <visual>
            <origin xyz="0 0 0" rpy="0 0 0" />
            <geometry>
                <<sphere radius="0.5"/>
            </geometry>
            <material name="red"/>
        </visual>
    </link>
    <joint name="joint_4" type="fixed">
        <parent link="link_3" />
        <child link="link_4" />
        <origin xyz="1.15 0 0" rpy="0 0 0" />
    </joint>

</robot>